<?xml version="1.0" ?>
<robot xmlns:xacro="http://ros.org/wiki/xacro">

  <!-- left leg -->
  <xacro:macro name="robotis_op3_l_arm" params="parent">

  <!-- left shoulder pitch joint -->
  <joint name="l_sho_pitch" type="revolute">
    <parent link="${parent}"/>
    <child link="l_sho_pitch_link"/>
    <origin xyz="-0.001 0.06 0.111" rpy="0 0 0" />
    <axis xyz="0 1 0" />
    <limit effort="1000" velocity="100" lower="${-pi*0.9}" upper="${pi*0.9}" />
    <dynamics damping="0.1" friction="0.0" />
  </joint>
  <!-- <xacro:insert_transmission name="l_sho_pitch" /> -->

  <!-- left shoulder pitch link -->
  <link name="l_sho_pitch_link">
    <visual>
      <xacro:insert_mesh_l_sho_pitch_link />
    </visual>
    <!-- <collision>
      <xacro:insert_mesh_l_sho_pitch_link />
    </collision> -->
    <collision>
      <origin xyz="0.000000 0.015500 -0.003750" rpy="0 0 0"/>
      <geometry>
        <box size="0.042000 0.031000 0.032500"/>
      </geometry>
    </collision>
    <inertial>
      <xacro:insert_inertia_l_sho_pitch_link />
    </inertial>
  </link>

  <!-- left shoulder roll joint -->
  <joint name="l_sho_roll" type="revolute">
    <parent link="l_sho_pitch_link"/>
    <child link="l_sho_roll_link"/>
    <origin xyz="0.019 0.0285 -0.010" rpy="0 0 0" />
    <axis xyz="-1 0 0" />
    <limit effort="1000" velocity="100" lower="${-pi*0.9}" upper="${pi*0.9}" />
    <dynamics damping="0.1" friction="0.0" />
  </joint>
  <!-- <xacro:insert_transmission name="l_sho_roll" /> -->

  <!-- left shoulder roll link -->
  <link name="l_sho_roll_link">
    <visual>
      <xacro:insert_mesh_l_sho_roll_link />
    </visual>
    <!-- <collision>
      <xacro:insert_mesh_l_sho_roll_link />
    </collision> -->
    <collision>
      <origin xyz="-0.016800 0.045200 0.000700" rpy="0 0 0"/>
      <geometry>
        <box size="0.042400 0.112900 0.030100"/>
      </geometry>
    </collision>
    <inertial>
      <xacro:insert_inertia_l_sho_roll_link />
    </inertial>
  </link>

  <!-- left elbow joint -->
  <joint name="l_el" type="revolute">
    <parent link="l_sho_roll_link"/>
    <child link="l_el_link"/>
    <origin xyz="0.0 0.0904 -0.0001" rpy="0 0 0" />
    <axis xyz="1 0 0" />
    <limit effort="1000" velocity="100" lower="${-pi*0.9}" upper="${pi*0.9}" />
    <dynamics damping="0.1" friction="0.0" />
  </joint>
  <!-- <xacro:insert_transmission name="l_el" /> -->

  <!-- left elbow link -->
  <link name="l_el_link">
    <visual>
      <xacro:insert_mesh_l_el_link />
    </visual>
    <!-- <collision>
      <xacro:insert_mesh_l_el_link />
    </collision> -->
    <collision>
      <origin xyz="-0.019000 0.072005 0.000000" rpy="0 0 0"/>
      <geometry>
        <box size="0.042000 0.149010 0.030000"/>
      </geometry>
    </collision>
    <inertial>
      <xacro:insert_inertia_l_el_link />
    </inertial>
  </link>

  </xacro:macro>

</robot>
